<?xml version="1.0" ?>
<!-- =================================================================================== -->
<!-- |    This document was autogenerated by xacro from goliath.xacro                  | -->
<!-- |    EDITING THIS FILE BY HAND IS NOT RECOMMENDED                                 | -->
<!-- =================================================================================== -->
<robot name="test_map">
  <!-- t265_odom_frame to t265_link transform -->
  <!-- This transform will be provided by the T265 tracking camera -->
  <link name="t265_odom_frame"/>
  <link name="t265_link"/>
  <joint name="t265_odom_frame_to_t265_link_joint" type="floating">
    <parent link="t265_odom_frame"/>
    <child link="t265_link"/>
  </joint>
  <!-- t265_link to base_link transform -->
  <link name="base_link"/>
  <joint name="t265_link_to_base_link_joint" type="fixed">
    <origin rpy="0 0 0" xyz="0 0 0"/>
    <parent link="t265_link"/>
    <child link="base_link"/>
  </joint>
  <!-- t265_link to d455_link transform -->
  <link name="d455_link"/>
  <joint name="t265_link_to_d455_link_joint" type="fixed">
    <origin rpy="0 0.218 0" xyz="0.045 0 0.09"/>
    <parent link="t265_link"/>
    <child link="d455_link"/>
  </joint>
</robot>

